WARNING    - 2024-03-22 12:38:17,755 - client          : PyNaCl is not installed, voice will NOT be supported
INFO       - 2024-03-22 12:38:17,762 - client          : logging in using static token
INFO       - 2024-03-22 12:38:18,580 - gateway         : Shard ID None has connected to Gateway (Session ID: 38f86ab1251a5b19d61ea0879dfc9461).
ERROR      - 2024-03-22 13:58:15,956 - client          : Attempting a reconnect in 0.45s
Traceback (most recent call last):
  File "C:\Users\E\Documents\discordbot\.venv\lib\site-packages\aiohttp\connector.py", line 1155, in _create_direct_connection
    hosts = await asyncio.shield(host_resolved)
  File "C:\Users\E\Documents\discordbot\.venv\lib\site-packages\aiohttp\connector.py", line 874, in _resolve_host
    addrs = await self._resolver.resolve(host, port, family=self._family)
  File "C:\Users\E\Documents\discordbot\.venv\lib\site-packages\aiohttp\resolver.py", line 33, in resolve
    infos = await self._loop.getaddrinfo(
  File "C:\Users\E\anaconda3\lib\asyncio\base_events.py", line 863, in getaddrinfo
    return await self.run_in_executor(
  File "C:\Users\E\anaconda3\lib\concurrent\futures\thread.py", line 58, in run
    result = self.fn(*self.args, **self.kwargs)
  File "C:\Users\E\anaconda3\lib\socket.py", line 955, in getaddrinfo
    for res in _socket.getaddrinfo(host, port, family, type, proto, flags):
socket.gaierror: [Errno 11001] getaddrinfo failed

The above exception was the direct cause of the following exception:

Traceback (most recent call last):
  File "C:\Users\E\Documents\discordbot\.venv\lib\site-packages\discord\client.py", line 656, in connect
    self.ws = await asyncio.wait_for(coro, timeout=60.0)
  File "C:\Users\E\anaconda3\lib\asyncio\tasks.py", line 445, in wait_for
    return fut.result()
  File "C:\Users\E\Documents\discordbot\.venv\lib\site-packages\discord\gateway.py", line 372, in from_client
    socket = await client.http.ws_connect(str(url))
  File "C:\Users\E\Documents\discordbot\.venv\lib\site-packages\discord\http.py", line 537, in ws_connect
    return await self.__session.ws_connect(url, **kwargs)
  File "C:\Users\E\Documents\discordbot\.venv\lib\site-packages\aiohttp\client.py", line 805, in _ws_connect
    resp = await self.request(
  File "C:\Users\E\Documents\discordbot\.venv\lib\site-packages\aiohttp\client.py", line 562, in _request
    conn = await self._connector.connect(
  File "C:\Users\E\Documents\discordbot\.venv\lib\site-packages\aiohttp\connector.py", line 540, in connect
    proto = await self._create_connection(req, traces, timeout)
  File "C:\Users\E\Documents\discordbot\.venv\lib\site-packages\aiohttp\connector.py", line 901, in _create_connection
    _, proto = await self._create_direct_connection(req, traces, timeout)
  File "C:\Users\E\Documents\discordbot\.venv\lib\site-packages\aiohttp\connector.py", line 1169, in _create_direct_connection
    raise ClientConnectorError(req.connection_key, exc) from exc
aiohttp.client_exceptions.ClientConnectorError: Cannot connect to host gateway-us-east1-d.discord.gg:443 ssl:default [getaddrinfo failed]
ERROR      - 2024-03-22 13:58:17,031 - client          : Attempting a reconnect in 1.67s
Traceback (most recent call last):
  File "C:\Users\E\Documents\discordbot\.venv\lib\site-packages\aiohttp\connector.py", line 1155, in _create_direct_connection
    hosts = await asyncio.shield(host_resolved)
  File "C:\Users\E\Documents\discordbot\.venv\lib\site-packages\aiohttp\connector.py", line 874, in _resolve_host
    addrs = await self._resolver.resolve(host, port, family=self._family)
  File "C:\Users\E\Documents\discordbot\.venv\lib\site-packages\aiohttp\resolver.py", line 33, in resolve
    infos = await self._loop.getaddrinfo(
  File "C:\Users\E\anaconda3\lib\asyncio\base_events.py", line 863, in getaddrinfo
    return await self.run_in_executor(
  File "C:\Users\E\anaconda3\lib\concurrent\futures\thread.py", line 58, in run
    result = self.fn(*self.args, **self.kwargs)
  File "C:\Users\E\anaconda3\lib\socket.py", line 955, in getaddrinfo
    for res in _socket.getaddrinfo(host, port, family, type, proto, flags):
socket.gaierror: [Errno 11001] getaddrinfo failed

The above exception was the direct cause of the following exception:

Traceback (most recent call last):
  File "C:\Users\E\Documents\discordbot\.venv\lib\site-packages\discord\client.py", line 656, in connect
    self.ws = await asyncio.wait_for(coro, timeout=60.0)
  File "C:\Users\E\anaconda3\lib\asyncio\tasks.py", line 445, in wait_for
    return fut.result()
  File "C:\Users\E\Documents\discordbot\.venv\lib\site-packages\discord\gateway.py", line 372, in from_client
    socket = await client.http.ws_connect(str(url))
  File "C:\Users\E\Documents\discordbot\.venv\lib\site-packages\discord\http.py", line 537, in ws_connect
    return await self.__session.ws_connect(url, **kwargs)
  File "C:\Users\E\Documents\discordbot\.venv\lib\site-packages\aiohttp\client.py", line 805, in _ws_connect
    resp = await self.request(
  File "C:\Users\E\Documents\discordbot\.venv\lib\site-packages\aiohttp\client.py", line 562, in _request
    conn = await self._connector.connect(
  File "C:\Users\E\Documents\discordbot\.venv\lib\site-packages\aiohttp\connector.py", line 540, in connect
    proto = await self._create_connection(req, traces, timeout)
  File "C:\Users\E\Documents\discordbot\.venv\lib\site-packages\aiohttp\connector.py", line 901, in _create_connection
    _, proto = await self._create_direct_connection(req, traces, timeout)
  File "C:\Users\E\Documents\discordbot\.venv\lib\site-packages\aiohttp\connector.py", line 1169, in _create_direct_connection
    raise ClientConnectorError(req.connection_key, exc) from exc
aiohttp.client_exceptions.ClientConnectorError: Cannot connect to host gateway-us-east1-d.discord.gg:443 ssl:default [getaddrinfo failed]
ERROR      - 2024-03-22 13:58:18,712 - client          : Attempting a reconnect in 2.88s
Traceback (most recent call last):
  File "C:\Users\E\Documents\discordbot\.venv\lib\site-packages\aiohttp\connector.py", line 1155, in _create_direct_connection
    hosts = await asyncio.shield(host_resolved)
  File "C:\Users\E\Documents\discordbot\.venv\lib\site-packages\aiohttp\connector.py", line 874, in _resolve_host
    addrs = await self._resolver.resolve(host, port, family=self._family)
  File "C:\Users\E\Documents\discordbot\.venv\lib\site-packages\aiohttp\resolver.py", line 33, in resolve
    infos = await self._loop.getaddrinfo(
  File "C:\Users\E\anaconda3\lib\asyncio\base_events.py", line 863, in getaddrinfo
    return await self.run_in_executor(
  File "C:\Users\E\anaconda3\lib\concurrent\futures\thread.py", line 58, in run
    result = self.fn(*self.args, **self.kwargs)
  File "C:\Users\E\anaconda3\lib\socket.py", line 955, in getaddrinfo
    for res in _socket.getaddrinfo(host, port, family, type, proto, flags):
socket.gaierror: [Errno 11001] getaddrinfo failed

The above exception was the direct cause of the following exception:

Traceback (most recent call last):
  File "C:\Users\E\Documents\discordbot\.venv\lib\site-packages\discord\client.py", line 656, in connect
    self.ws = await asyncio.wait_for(coro, timeout=60.0)
  File "C:\Users\E\anaconda3\lib\asyncio\tasks.py", line 445, in wait_for
    return fut.result()
  File "C:\Users\E\Documents\discordbot\.venv\lib\site-packages\discord\gateway.py", line 372, in from_client
    socket = await client.http.ws_connect(str(url))
  File "C:\Users\E\Documents\discordbot\.venv\lib\site-packages\discord\http.py", line 537, in ws_connect
    return await self.__session.ws_connect(url, **kwargs)
  File "C:\Users\E\Documents\discordbot\.venv\lib\site-packages\aiohttp\client.py", line 805, in _ws_connect
    resp = await self.request(
  File "C:\Users\E\Documents\discordbot\.venv\lib\site-packages\aiohttp\client.py", line 562, in _request
    conn = await self._connector.connect(
  File "C:\Users\E\Documents\discordbot\.venv\lib\site-packages\aiohttp\connector.py", line 540, in connect
    proto = await self._create_connection(req, traces, timeout)
  File "C:\Users\E\Documents\discordbot\.venv\lib\site-packages\aiohttp\connector.py", line 901, in _create_connection
    _, proto = await self._create_direct_connection(req, traces, timeout)
  File "C:\Users\E\Documents\discordbot\.venv\lib\site-packages\aiohttp\connector.py", line 1169, in _create_direct_connection
    raise ClientConnectorError(req.connection_key, exc) from exc
aiohttp.client_exceptions.ClientConnectorError: Cannot connect to host gateway-us-east1-d.discord.gg:443 ssl:default [getaddrinfo failed]
INFO       - 2024-03-22 13:58:21,820 - gateway         : Shard ID None session has been invalidated.
INFO       - 2024-03-22 13:58:27,179 - gateway         : Shard ID None has connected to Gateway (Session ID: 32f5c02d35239b470cc40a5498eb27b1).
ERROR      - 2024-03-22 13:58:29,218 - client          : Ignoring exception in on_ready
Traceback (most recent call last):
  File "C:\Users\E\Documents\discordbot\.venv\lib\site-packages\discord\client.py", line 441, in _run_event
    await coro(*args, **kwargs)
  File "C:\Users\E\Documents\discordbot\main.py", line 19, in on_ready
    await bot.load_extension("cogs.minigame")
  File "C:\Users\E\Documents\discordbot\.venv\lib\site-packages\discord\ext\commands\bot.py", line 1007, in load_extension
    raise errors.ExtensionAlreadyLoaded(name)
discord.ext.commands.errors.ExtensionAlreadyLoaded: Extension 'cogs.minigame' is already loaded.
INFO       - 2024-03-22 16:57:04,487 - gateway         : Shard ID None has successfully RESUMED session 32f5c02d35239b470cc40a5498eb27b1.
